Workbook
Name \A: #REF!
Name \C: #REF!
Name \D: #REF!
Name \E: #REF!
Name \F: #REF!
Name \G: #REF!
Name \H: #REF!
Name \J: #REF!
Name \M: #REF!
Name \N: #REF!
Name \P: #REF!
Name \Q: #REF!
Name \R: #REF!
Name \S: #REF!
Name \T: #REF!
Name \V: #REF!
Name \X: #REF!
Name \Z: #REF!
Name ___________DAT45: #REF!
Name ___________DAT46: #REF!
Name ___________DAT47: #REF!
Name ___________DAT48: #REF!
Name ___________DAT5: #REF!
Name ___________DAT6: #REF!
Name ___________DAT7: #REF!
Name ___________DAT8: #REF!
Name ___________DAT9: #REF!
Name ___________prn01: #REF!
Name __________DAT1: #REF!
Name __________DAT10: #REF!
Name __________DAT11: #REF!
Name __________DAT12: #REF!
Name __________DAT13: #REF!
Name __________DAT14: #REF!
Name __________DAT15: #REF!
Name __________DAT16: #REF!
Name __________DAT17: #REF!
Name __________DAT18: #REF!
Name __________DAT19: #REF!
Name __________DAT2: #REF!
Name __________DAT20: #REF!
Name __________DAT21: #REF!
Name __________DAT22: #REF!
Name __________DAT23: #REF!
Name __________DAT24: #REF!
Name __________DAT25: #REF!
Name __________DAT26: #REF!
Name __________DAT27: #REF!
Name __________DAT28: #REF!
Name __________DAT29: #REF!
Name __________DAT3: #REF!
Name __________DAT30: #REF!
Name __________DAT31: #REF!
Name __________DAT32: #REF!
Name __________DAT33: #REF!
Name __________DAT34: #REF!
Name __________DAT35: #REF!
Name __________DAT36: #REF!
Name __________DAT37: #REF!
Name __________DAT38: #REF!

Sheet Rugs
A1: Location | B1: Business | C1: Section | D1: Sr_No | E1: Dept_Machine_Name | F1: Designation | G1: Machine_Count | H1: Workload | I1: Formulas | J1: BE_Scientific_Manpower | K1: Operator_Type | L1: Contractors | M1: Company_Associate | N1: BE_Final_Manpower | O1: N_shift | P1: General_Shift | Q1: Shift_A | R1: Shift_B | S1: Shift_C | T1: Reliever | U1: Remarks
A2: Vapi | B2: Rugs | C2: CHENILLE | D2: 1 | E2: Chenille Machine | F2: Chenille mc Operator | G2: 3 | H2: 2 operator/machine | I2: (3*2)*3 | J2: 18 | K2: Direct | L2: 0 | M2: 18 | N2: 18 | O2: 3 | P2: 0 | Q2: 6 | R2: 6 | S2: 6 | T2: 0
A3: Vapi | B3: Rugs | C3: CHENILLE | D3: 2 | E3: Chenille Machine | F3: Winding mc Operator | G3: 1 | H3: 1 operator/machine | I3: (1*1)*3 | J3: 3 | L3: 0 | M3: 3 | N3: 3 | O3: 3 | P3: 0 | Q3: 1 | R3: 1 | S3: 1 | T3: 0
A4: Vapi | B4: Rugs | C4: CHENILLE | D4: 3 | E4: Chenille Machine | F4: Jobber | G4: 1 | H4: 1 jobber/machine | I4: (1*1)*3 | J4: 3 | L4: 0 | M4: 3 | N4: 3 | O4: 3 | P4: 0 | Q4: 1 | R4: 1 | S4: 1 | T4: 0
A5: Vapi | B5: Rugs | C5: CHENILLE | D5: 4 | E5: Chenille Machine | F5: Fitter | G5: 3 | H5: 0 (not required) | I5: (3*0)*3 | J5: 0 | L5: 0 | M5: 0 | N5: 0 | O5: 0 | P5: 0 | Q5: 0 | R5: 0 | S5: 0 | T5: 0
A6: Vapi | B6: Rugs | C6: CHENILLE | D6: 5 | E6: Chenille Machine | F6: Material Handling | G6: 1 | H6: 1 person/machine | I6: (1*1)*3 | J6: 3 | L6: 3 | M6: 0 | N6: 3 | O6: 3 | P6: 0 | Q6: 1 | R6: 1 | S6: 1 | T6: 0
A7: Vapi | B7: Rugs | C7: Yarn Warehouse | D7: 1 | E7: Yarn Storage | F7: Jobber | G7: 0 | H7: 1 person | I7: (0*1)*3 | J7: 0 | L7: 0 | M7: 0 | N7: 0 | O7: 3 | P7: 0 | Q7: 0 | R7: 0 | S7: 0 | T7: 0
A8: Vapi | B8: Rugs | C8: Yarn Warehouse | D8: 2 | E8: Yarn Storage | F8: Material Handler (Loading, Unloading by Hand Staker) | G8: 1 | H8: 2 person/machine | I8: (1*2)*3 | J8: 6 | L8: 6 | M8: 0 | N8: 6 | O8: 3 | P8: 0 | Q8: 2 | R8: 2 | S8: 2 | T8: 0
A9: Vapi | B9: Rugs | C9: Table Tufting | D9: 1 | E9: Tufting | F9: Operator | G9: 1 | H9: 0 (not required) | I9: (1*0)*3 | J9: 0 | L9: 0 | M9: 0 | N9: 0 | O9: 1 | P9: 0 | Q9: 0 | R9: 0 | S9: 0 | T9: 0
A10: Vapi | B10: Rugs | C10: Table Tufting | D10: 2 | E10: Tufting | F10: Jobber | G10: 1 | H10: 1 jobber | I10: (1*1)*1 | J10: 1 | L10: 0 | M10: 1 | N10: 1 | O10: 1 | P10: 0 | Q10: 1 | R10: 0 | S10: 0 | T10: 0
A11: Vapi | B11: Rugs | C11: Machine Tufting | D11: 1 | E11: Machine Tufting | F11: Operator | G11: 2 | H11: 2 operator/machine | I11: (2*2)*2 | J11: 8 | L11: 0 | M11: 8 | N11: 8 | O11: 2 | P11: 0 | Q11: 4 | R11: 4 | S11: 0 | T11: 0
A12: Vapi | B12: Rugs | C12: Machine Tufting | D12: 2 | E12: Machine Tufting | F12: Jobber / DEO | G12: 1 | H12: 1 person/shift | I12: (1*1)*2 | J12: 2 | L12: 0 | M12: 2 | N12: 2 | O12: 2 | P12: 0 | Q12: 1 | R12: 1 | S12: 0 | T12: 0
A13: Vapi | B13: Rugs | C13: Machine Tufting | D13: 3 | E13: Machine Tufting | F13: Creel Boy | G13: 2 | H13: 2 person/machine | I13: (2*2)*2 | J13: 8 | L13: 8 | M13: 0 | N13: 8 | O13: 2 | P13: 0 | Q13: 4 | R13: 4 | S13: 0 | T13: 0
A14: Vapi | B14: Rugs | C14: Machine Tufting | D14: 4 | E14: CHENILE LENGTH CUTTING | F14: Operator | G14: 1 | H14: 1 operator/machine | I14: (1*1)*2 | J14: 2 | L14: 0 | M14: 2 | N14: 2 | O14: 2 | P14: 0 | Q14: 1 | R14: 1 | S14: 0 | T14: 0
... A21: Vapi | B21: Rugs | C21: Roll Receiving | D21: 6 | E21: Conveyor | F21: Jobber (Roll Finding, Entry in System, Bin Updattion) | G21: 0 | H21: 1 jobber/machine | I21: (0*1)*1 | J21: 0 | L21: 0 | M21: 0 | N21: 0 | O21: 1 | P21: 0 | Q21: 0 | R21: 0 | S21: 0 | T21: 0
A22: Vapi | B22: Rugs | C22: Coating | D22: 1 | E22: Latex Coating | F22: OPERATOR (MONORAIL-ROLL RECEIVING, ROLL STORAGE & SHIFTING) | G22: 1 | H22: 2 operator/machine | I22: (1*2)*3 | J22: 6 | L22: 6 | M22: 0 | N22: 6 | O22: =ROUNDUP((Coating!$C$13/(1/3)),0) -> 3 | P22: 0 | Q22: 2 | R22: 2 | S22: 2 | T22: 0
A23: Vapi | B23: Rugs | C23: Coating | D23: 2 | E23: Latex Coating | F23: OPERATOR (RE-ROLLING) | G23: 0 | H23: 0 (not required) | I23: (0*0)*3 | J23: 0 | L23: 0 | M23: 0 | N23: 0 | O23: =ROUNDUP((Coating!$C$13/(1/3)),0) -> 3 | P23: 0 | Q23: 0 | R23: 0 | S23: 0 | T23: 0
A24: Vapi | B24: Rugs | C24: Coating | D24: 3 | E24: Latex Coating | F24: OPERATOR (STITCHING & Feeding) | G24: =Coating!$C$13 -> 0.73804571 | H24: 1 operator/machine | I24: (1*1)*2.15 | J24: 2.15 | L24: 0 | M24: 3 | N24: 3 | O24: =ROUNDUP((Coating!$C$13/(1/3)),0) -> 3 | P24: 0 | Q24: 1 | R24: 1 | S24: 1 | T24: 0
A25: Vapi | B25: Rugs | C25: Coating | D25: 4 | E25: Latex Coating | F25: OPERATOR (PRE-COAT APPLICATION HEAD) | G25: =Coating!$C$13 -> 0.73804571 | H25: 1 operator/machine | I25: (1*1)*2.15 | J25: 2.15 | L25: 0 | M25: 3 | N25: 3 | O25: =ROUNDUP((Coating!$C$13/(1/3)),0) -> 3 | P25: 0 | Q25: 1 | R25: 1 | S25: 1 | T25: 0
A26: Vapi | B26: Rugs | C26: Coating | D26: 5 | E26: Latex Coating | F26: OPERATOR (MAIN COAT APPLICATION HEAD) | G26: =Coating!$C$13 -> 0.73804571 | H26: 1 operator/machine | I26: (1*1)*2.15 | J26: 2.15 | L26: 0 | M26: 3 | N26: 3 | O26: =ROUNDUP((Coating!$C$13/(1/3)),0) -> 3 | P26: 0 | Q26: 1 | R26: 1 | S26: 1 | T26: 0
A27: Vapi | B27: Rugs | C27: Coating | D27: 6 | E27: Latex Coating | F27: OPERATOR (LATEX KITCHEN) | G27: =Coating!$C$13 -> 0.73804571 | H27: 1 operator/machine | I27: (1*1)*2.15 | J27: 2.15 | L27: 0 | M27: 3 | N27: 3 | O27: =ROUNDUP((Coating!$C$13/(1/3)),0) -> 3 | P27: 0 | Q27: 1 | R27: 1 | S27: 1 | T27: 0
A28: Vapi | B28: Rugs | C28: Coating | D28: 7 | E28: Latex Coating | F28: OPERATOR (ROLL WINDING, STAKING) | G28: 1 | H28: 2 operator/machine | I28: (1*2)*3 | J28: 6 | L28: 6 | M28: 0 | N28: 6 | O28: =ROUNDUP((Coating!$C$13/(1/3)),0) -> 3 | P28: 0 | Q28: 2 | R28: 2 | S28: 2 | T28: 0
A29: Vapi | B29: Rugs | C29: Coating | D29: 8 | E29: Latex Coating | F29: JOBBER (PRE COAT, MAIN COAT) | G29: 1 | H29: 1 jobber/machine | I29: (1*1)*3 | J29: 3 | L29: 0 | M29: 3 | N29: 3 | O29: =ROUNDUP((Coating!$C$13/(1/3)),0) -> 3 | P29: 0 | Q29: 1 | R29: 1 | S29: 1 | T29: 0
A30: Vapi | B30: Rugs | C30: Coating | D30: 9 | E30: Latex Coating | F30: MATERIAL HANDLER (CLEANING & WASTAGE DISPOSEL) | G30: 1 | H30: 2 person/machine | I30: (1*2)*3 | J30: 6 | L30: 6 | M30: 0 | N30: 6 | O30: =ROUNDUP((Coating!$C$13/(1/3)),0) -> 3 | P30: 0 | Q30: 2 | R30: 2 | S30: 2 | T30: 0
A31: Vapi | B31: Rugs | C31: Coating | D31: 10 | E31: Latex Coating | F31: DATA OPERATOR / MONITOR | G31: 1 | H31: 1 person/machine | I31: (1*1)*3 | J31: 3 | L31: 0 | M31: 3 | N31: 3 | O31: =ROUNDUP((Coating!$C$13/(1/3)),0) -> 3 | P31: 0 | Q31: 1 | R31: 1 | S31: 1 | T31: 0
A32: Vapi | B32: Rugs | C32: Coating | D32: 11 | E32: Latex Coating | F32: OPERATOR (PCS RECOVERY) | G32: 1 | H32: 3 operator/machine | I32: (1*3)*3 | J32: 9 | L32: 9 | M32: 2 | N32: 11 | O32: =ROUNDUP((Coating!$C$13/(1/3)),0) -> 3 | P32: 0 | Q32: 4 | R32: 4 | S32: 4 | T32: 0
A33: Vapi | B33: Rugs | C33: Coating | D33: 12 | E33: Latex Compaunding | F33: OPERATOR (RAW MATERIAL LOADING AND MIXING) | G33: 1 | H33: 3 operator/machine | I33: (1*3)*3 | J33: 9 | L33: 9 | M33: 0 | N33: 9 | O33: =ROUNDUP((Coating!$C$13/(1/3)),0) -> 3 | P33: 0 | Q33: 3 | R33: 3 | S33: 3 | T33: 0
A34: Vapi | B34: Rugs | C34: Cut & Sew | D34: 1 | E34: Length Cutting | F34: Operator | G34: =ROUND(CS!$D$56,0) -> 1 | H34: 1 operator/machine | I34: (1*1)*3 | J34: 2.04 | L34: 0 | M34: 3 | N34: 3 | O34: 3 | P34: 0 | Q34: 1 | R34: 1 | S34: 1 | T34: 0
A35: Vapi | B35: Rugs | C35: Cut & Sew | D35: 2 | E35: Length Cutting | F35: Operator (Roll Feeder / Roll to Roll stitching) | G35: =ROUND(CS!$D$56,0) -> 1 | H35: 2 operator/machine | I35: (1*2)*3 | J35: 6 | L35: 6 | M35: 0 | N35: 6 | O35: 3 | P35: 0 | Q35: 2 | R35: 2 | S35: 2 | T35: 0
A36: Vapi | B36: Rugs | C36: Cut & Sew | D36: 3 | E36: Length Cutting | F36: Material Handler | G36: =ROUND(CS!$D$56,0) -> 1 | H36: 1 person/machine | I36: (1*1)*3 | J36: 3 | L36: 3 | M36: 0 | N36: 3 | O36: 3 | P36: 0 | Q36: 1 | R36: 1 | S36: 1 | T36: 0
A37: Vapi | B37: Rugs | C37: Cut & Sew | D37: 4 | E37: Length Over edging | F37: Operator | G37: =ROUNDUP(CS!D61,0) -> 3 | H37: 1 operator/machine | I37: (3*1)*3 | J37: 9 | L37: 0 | M37: 9 | N37: 9 | O37: 3 | P37: 0 | Q37: 3 | R37: 3 | S37: 3 | T37: 0
A38: Vapi | B38: Rugs | C38: Cut & Sew | D38: 5 | E38: Length Over edging | F38: Material Handler (Trolly movment) | G38: 2 | H38: 1 person/machine | I38: (2*1)*3 | J38: 6 | L38: 6 | M38: 0 | N38: 6 | O38: 3 | P38: 0 | Q38: 2 | R38: 2 | S38: 2 | T38: 0
A39: Vapi | B39: Rugs | C39: Cut & Sew | D39: 6 | E39: Automaic Shape Cutting m/c | F39: Cutter Operator | G39: =ROUNDUP(CS!$D$70,0) -> 1 | H39: 1 operator/machine | I39: (1*1)*3 | J39: 3 | L39: 0 | M39: 3 | N39: 3 | O39: 3 | P39: 0 | Q39: 1 | R39: 1 | S39: 1 | T39: 0
A40: Vapi | B40: Rugs | C40: Cut & Sew | D40: 7 | E40: Automaic Shape Cutting m/c | F40: Spreader Operator /layering | G40: =ROUNDUP(CS!$D$70,0) -> 1 | H40: 1 operator/machine | I40: (1*1)*3 | J40: 3 | L40: 3 | M40: 0 | N40: 3 | O40: 3 | P40: 0 | Q40: 1 | R40: 1 | S40: 1 | T40: 0
A41: Vapi | B41: Rugs | C41: Cut & Sew | D41: 8 | E41: Automaic Shape Cutting m/c | F41: Material Handler | G41: =ROUNDUP(CS!$D$70,0) -> 1 | H41: 2 person/machine | I41: (1*2)*3 | J41: 6 | L41: 6 | M41: 0 | N41: 6 | O41: 3 | P41: 0 | Q41: 2 | R41: 2 | S41: 2 | T41: 0
A42: Vapi | B42: Rugs | C42: Cut & Sew | D42: 9 | E42: Cross Cutting | F42: Operator | G42: =ROUND(CS!D61,0) -> 2 | H42: 1 operator/machine | I42: (2*1)*3 | J42: 6 | L42: 0 | M42: 6 | N42: 6 | O42: 3 | P42: 0 | Q42: 2 | R42: 2 | S42: 2 | T42: 0
A43: Vapi | B43: Rugs | C43: Cut & Sew | D43: 10 | E43: Cross Cutting | F43: Material Handler (Pcs Collating, Bundling, Palating,Shifting) | G43: 1 | H43: 2 person/machine | I43: (1*2)*3 | J43: 6 | L43: 6 | M43: 0 | N43: 6 | O43: 3 | P43: 0 | Q43: 2 | R43: 2 | S43: 2 | T43: 0
A44: Vapi | B44: Rugs | C44: Cut & Sew | D44: 11 | E44: Manual Cutting | F44: (750 Pcs Per Person output considered) | G44: =ROUNDUP(CS!D66/3,0) -> 10 | H44: 1 person | I44: (10*1)*3 | J44: 28.9 | L44: 29 | M44: 29 | N44: 58 | O44: 3 | P44: 0 | Q44: 19 | R44: 19 | S44: 19 | T44: 0
A45: Vapi | B45: Rugs | C45: Cut & Sew | D45: 12 | E45: Piping / Canvs Cutting | F45: Operator | G45: 1 | H45: 0 (not required) | I45: (1*0)*3 | J45: 0 | L45: 0 | M45: 0 | N45: 0 | O45: 3 | P45: 0 | Q45: 0 | R45: 0 | S45: 0 | T45: 0
A46: Vapi | B46: Rugs | C46: Cut & Sew | D46: 13 | E46: Trims / Wastage Collection | F46: Material Handler | G46: 1 | H46: 1 person/machine | I46: (1*1)*3 | J46: 3 | L46: 3 | M46: 0 | N46: 3 | O46: 3 | P46: 0 | Q46: 1 | R46: 1 | S46: 1 | T46: 0
...

Sheet Packing&TQM
A2: Type | B2: Line | C2: Req/Day | D2: Production Capacity | E2: Reqd. Lines | F2: TQM Capacity | G2: TQM
A3: Drylon | B3: Smart Line | C3: =Capacity!F5+Capacity!F6 -> 55840.538 | D3: 4500 | E3: 2 | F3: 1200 | G3: =D3/F3 -> 3.75
A4: Drylon | B4: INA | C4: =C3 -> 55840.538 | D4: 4500 | E4: 2.1 | F4: 1200 | G4: =D4/F4 -> 3.75
A5: Chenille | B5: Manual (Chenille) | C5: =Capacity!F4 -> 11889 | D5: 1500 | E5: 2.6 | F5: 1500 | G5: =D5/F5 -> 1
A6: Cotton | B6: Manual (Cotton) | C6: =Packing!E24 -> 2365 | D6: 1500 | E6: 0.5 | F6: 800 | G6: =D6/F6 -> 1.875
A10: Location | B10: Business | C10: Section | D10: Sr_No | E10: Dept_Machine_Name | F10: Designation | G10: Machine_Count | H10: Workload | I10: Formulas | J10: BE_Scientific_Manpower | K10: Operator_Type | L10: Contractors | M10: Company_Associate | N10: BE_Final_Manpower | O10: N_shifts | P10: General_Shift | Q10: Shift_A | R10: Shift_B | S10: Shift_C | T10: Reliever | U10: Remarks
A11: Vapi | B11: Rugs | C11: Packing Line MP | D11: 1 | E11: Smart Line | F11: Loading | G11: =$E$3 -> 2 | H11: 1 person/line/shift | I11: (2.0*1)*3 | J11: =G11*1*3 -> 6 | L11: 0 | M11: =N11 -> 6 | N11: =ROUND(J11,0) -> 6 | O11: 3 | P11: 0 | Q11: =ROUNDDOWN(N11/3,0) -> 2 | R11: =ROUNDDOWN(N11/3,0) -> 2 | S11: =N11-Q11-R11 -> 2 | T11: 0 | U11: Drylon
A12: Vapi | B12: Rugs | C12: Packing Line MP | D12: 2 | E12: Smart Line | F12: Tailor | G12: =$E$3 -> 2 | H12: 3 tailor/line/shift | I12: (2.0*3)*3 | J12: =G12*3*3 -> 18 | L12: 0 | M12: =N12 -> 18 | N12: =ROUND(J12,0) -> 18 | O12: 3 | P12: 0 | Q12: =ROUNDDOWN(N12/3,0) -> 6 | R12: =ROUNDDOWN(N12/3,0) -> 6 | S12: =N12-Q12-R12 -> 6 | T12: 0 | U12: Drylon
A13: Vapi | B13: Rugs | C13: Packing Line MP | D13: 3 | E13: Smart Line | F13: Finisher | G13: =$E$3 -> 2 | H13: 6 finisher/line/shift | I13: (2.0*6)*3 | J13: =G13*6*3 -> 36 | L13: 0 | M13: =N13 -> 36 | N13: =ROUND(J13,0) -> 36 | O13: 3 | P13: 0 | Q13: =ROUNDDOWN(N13/3,0) -> 12 | R13: =ROUNDDOWN(N13/3,0) -> 12 | S13: =N13-Q13-R13 -> 12 | T13: 0 | U13: Drylon
A14: Vapi | B14: Rugs | C14: Packing Line MP | D14: 4 | E14: Smart Line | F14: Hot Air | G14: =$E$3 -> 2 | H14: 2 person/line/shift | I14: (2.0*2)*3 | J14: =G14*2*3 -> 12 | L14: 0 | M14: =N14 -> 12 | N14: =ROUND(J14,0) -> 12 | O14: 3 | P14: 0 | Q14: =ROUNDDOWN(N14/3,0) -> 4 | R14: =ROUNDDOWN(N14/3,0) -> 4 | S14: =N14-Q14-R14 -> 4 | T14: 0 | U14: Drylon
A15: Vapi | B15: Rugs | C15: Packing Line MP | D15: 5 | E15: Smart Line | F15: UL & AC | G15: =$E$3 -> 2 | H15: 1 person/line/shift | I15: (2.0*1)*3 | J15: =G15*1*3 -> 6 | L15: 0 | M15: =N15 -> 6 | N15: =ROUND(J15,0) -> 6 | O15: 3 | P15: 0 | Q15: =ROUNDDOWN(N15/3,0) -> 2 | R15: =ROUNDDOWN(N15/3,0) -> 2 | S15: =N15-Q15-R15 -> 2 | T15: 0 | U15: Drylon
A16: Vapi | B16: Rugs | C16: Packing Line MP | D16: 6 | E16: Smart Line | F16: Gunner | G16: =$E$3 -> 2 | H16: 1 person/line/shift | I16: (2.0*1)*3 | J16: =G16*1*3 -> 6 | L16: 0 | M16: =N16 -> 6 | N16: =ROUND(J16,0) -> 6 | O16: 3 | P16: 0 | Q16: =ROUNDDOWN(N16/3,0) -> 2 | R16: =ROUNDDOWN(N16/3,0) -> 2 | S16: =N16-Q16-R16 -> 2 | T16: 0 | U16: Drylon
A17: Vapi | B17: Rugs | C17: Packing Line MP | D17: 7 | E17: Smart Line | F17: Poly Packer | G17: =$E$3 -> 2 | H17: 4 person/line/shift | I17: (2.0*4)*3 | J17: =G17*4*3 -> 24 | L17: 0 | M17: =N17 -> 24 | N17: =ROUND(J17,0) -> 24 | O17: 3 | P17: 0 | Q17: =ROUNDDOWN(N17/3,0) -> 8 | R17: =ROUNDDOWN(N17/3,0) -> 8 | S17: =N17-Q17-R17 -> 8 | T17: 0 | U17: Drylon
A18: Vapi | B18: Rugs | C18: Packing Line MP | D18: 8 | E18: INA | F18: Loading | G18: =$E$4 -> 2.1 | H18: 1 person/line/shift | I18: (2.1*1)*3 | J18: =G18*1*3 -> 6.3 | L18: 0 | M18: =N18 -> 6 | N18: =ROUND(J18,0) -> 6 | O18: 3 | P18: 0 | Q18: =ROUNDDOWN(N18/3,0) -> 2 | R18: =ROUNDDOWN(N18/3,0) -> 2 | S18: =N18-Q18-R18 -> 2 | T18: 0 | U18: Drylon
A19: Vapi | B19: Rugs | C19: Packing Line MP | D19: 9 | E19: INA | F19: Tailor | G19: =$E$4 -> 2.1 | H19: 3 tailor/line/shift | I19: (2.1*3)*3 | J19: =G19*3*3 -> 18.9 | L19: 0 | M19: =N19 -> 19 | N19: =ROUND(J19,0) -> 19 | O19: 3 | P19: 0 | Q19: =ROUNDDOWN(N19/3,0) -> 6 | R19: =ROUNDDOWN(N19/3,0) -> 6 | S19: =N19-Q19-R19 -> 7 | T19: 0 | U19: Drylon
A20: Vapi | B20: Rugs | C20: Packing Line MP | D20: 10 | E20: INA | F20: Finisher | G20: =$E$4 -> 2.1 | H20: 6 finisher/line/shift | I20: (2.1*6)*3 | J20: =G20*6*3 -> 37.8 | L20: 0 | M20: =N20 -> 38 | N20: =ROUND(J20,0) -> 38 | O20: 3 | P20: 0 | Q20: =ROUNDDOWN(N20/3,0) -> 12 | R20: =ROUNDDOWN(N20/3,0) -> 12 | S20: =N20-Q20-R20 -> 14 | T20: 0 | U20: Drylon
A21: Vapi | B21: Rugs | C21: Packing Line MP | D21: 11 | E21: INA | F21: Hot Air | G21: =$E$4 -> 2.1 | H21: 2 person/line/shift | I21: (2.1*2)*3 | J21: =G21*2*3 -> 12.6 | L21: 0 | M21: =N21 -> 13 | N21: =ROUND(J21,0) -> 13 | O21: 3 | P21: 0 | Q21: =ROUNDDOWN(N21/3,0) -> 4 | R21: =ROUNDDOWN(N21/3,0) -> 4 | S21: =N21-Q21-R21 -> 5 | T21: 0 | U21: Drylon
A22: Vapi | B22: Rugs | C22: Packing Line MP | D22: 12 | E22: INA | F22: UL & AC | G22: =$E$4 -> 2.1 | H22: 1 person/line/shift | I22: (2.1*1)*3 | J22: =G22*1*3 -> 6.3 | L22: 0 | M22: =N22 -> 6 | N22: =ROUND(J22,0) -> 6 | O22: 3 | P22: 0 | Q22: =ROUNDDOWN(N22/3,0) -> 2 | R22: =ROUNDDOWN(N22/3,0) -> 2 | S22: =N22-Q22-R22 -> 2 | T22: 0 | U22: Drylon
A23: Vapi | B23: Rugs | C23: Packing Line MP | D23: 13 | E23: INA | F23: Gunner | G23: =$E$4 -> 2.1 | H23: 1 person/line/shift | I23: (2.1*1)*3 | J23: =G23*1*3 -> 6.3 | L23: 0 | M23: =N23 -> 6 | N23: =ROUND(J23,0) -> 6 | O23: 3 | P23: 0 | Q23: =ROUNDDOWN(N23/3,0) -> 2 | R23: =ROUNDDOWN(N23/3,0) -> 2 | S23: =N23-Q23-R23 -> 2 | T23: 0 | U23: Drylon
A24: Vapi | B24: Rugs | C24: Packing Line MP | D24: 14 | E24: INA | F24: Poly Packer | G24: =$E$4 -> 2.1 | H24: 4 person/line/shift | I24: (2.1*4)*3 | J24: =G24*4*3 -> 25.2 | L24: 0 | M24: =N24 -> 25 | N24: =ROUND(J24,0) -> 25 | O24: 3 | P24: 0 | Q24: =ROUNDDOWN(N24/3,0) -> 8 | R24: =ROUNDDOWN(N24/3,0) -> 8 | S24: =N24-Q24-R24 -> 9 | T24: 0 | U24: Drylon
A25: Vapi | B25: Rugs | C25: Packing Line MP | D25: 15 | E25: Manual (Chenille) | F25: Loading | G25: =$E$5 -> 2.6 | H25: 1 person/line/shift | I25: (2.6*1)*3 | J25: =G25*1*3 -> 7.8 | L25: 0 | M25: =N25 -> 8 | N25: =ROUND(J25,0) -> 8 | O25: 3 | P25: 0 | Q25: =ROUNDDOWN(N25/3,0) -> 2 | R25: =ROUNDDOWN(N25/3,0) -> 2 | S25: =N25-Q25-R25 -> 4 | T25: 0 | U25: Chenille
A26: Vapi | B26: Rugs | C26: Packing Line MP | D26: 16 | E26: Manual (Chenille) | F26: Tailor | G26: =$E$5 -> 2.6 | H26: 1 tailor/line/shift | I26: (2.6*1)*3 | J26: =G26*1*3 -> 7.8 | L26: 0 | M26: =N26 -> 8 | N26: =ROUND(J26,0) -> 8 | O26: 3 | P26: 0 | Q26: =ROUNDDOWN(N26/3,0) -> 2 | R26: =ROUNDDOWN(N26/3,0) -> 2 | S26: =N26-Q26-R26 -> 4 | T26: 0 | U26: Chenille
A27: Vapi | B27: Rugs | C27: Packing Line MP | D27: 17 | E27: Manual (Chenille) | F27: Finisher | G27: =$E$5 -> 2.6 | H27: 2 finisher/line/shift | I27: (2.6*2)*3 | J27: =G27*2*3 -> 15.6 | L27: 0 | M27: =N27 -> 16 | N27: =ROUND(J27,0) -> 16 | O27: 3 | P27: 0 | Q27: =ROUNDDOWN(N27/3,0) -> 5 | R27: =ROUNDDOWN(N27/3,0) -> 5 | S27: =N27-Q27-R27 -> 6 | T27: 0 | U27: Chenille
A28: Vapi | B28: Rugs | C28: Packing Line MP | D28: 18 | E28: Manual (Chenille) | F28: Hot Air | G28: =$E$5 -> 2.6 | H28: 1 person/line/shift | I28: (2.6*1)*3 | J28: =G28*1*3 -> 7.8 | L28: 0 | M28: =N28 -> 8 | N28: =ROUND(J28,0) -> 8 | O28: 3 | P28: 0 | Q28: =ROUNDDOWN(N28/3,0) -> 2 | R28: =ROUNDDOWN(N28/3,0) -> 2 | S28: =N28-Q28-R28 -> 4 | T28: 0 | U28: Chenille
A29: Vapi | B29: Rugs | C29: Packing Line MP | D29: 19 | E29: Manual (Chenille) | F29: UL & AC | G29: =$E$5 -> 2.6 | H29: 0 person/line/shift | I29: (2.6*0)*3 | J29: =G29*0*3 -> 0 | L29: 0 | M29: =N29 -> 0 | N29: =ROUND(J29,0) -> 0 | O29: 3 | P29: 0 | Q29: =ROUNDDOWN(N29/3,0) -> 0 | R29: =ROUNDDOWN(N29/3,0) -> 0 | S29: =N29-Q29-R29 -> 0 | T29: 0 | U29: Chenille
A30: Vapi | B30: Rugs | C30: Packing Line MP | D30: 20 | E30: Manual (Chenille) | F30: Gunner | G30: =$E$5 -> 2.6 | H30: 1 person/line/shift | I30: (2.6*1)*3 | J30: =G30*1*3 -> 7.8 | L30: 0 | M30: =N30 -> 8 | N30: =ROUND(J30,0) -> 8 | O30: 3 | P30: 0 | Q30: =ROUNDDOWN(N30/3,0) -> 2 | R30: =ROUNDDOWN(N30/3,0) -> 2 | S30: =N30-Q30-R30 -> 4 | T30: 0 | U30: Chenille
A31: Vapi | B31: Rugs | C31: Packing Line MP | D31: 21 | E31: Manual (Chenille) | F31: Poly Packer | G31: =$E$5 -> 2.6 | H31: 4 person/line/shift | I31: (2.6*4)*3 | J31: =G31*4*3 -> 31.2 | L31: 0 | M31: =N31 -> 31 | N31: =ROUND(J31,0) -> 31 | O31: 3 | P31: 0 | Q31: =ROUNDDOWN(N31/3,0) -> 10 | R31: =ROUNDDOWN(N31/3,0) -> 10 | S31: =N31-Q31-R31 -> 11 | T31: 0 | U31: Chenille
A32: Vapi | B32: Rugs | C32: Packing Line MP | D32: 22 | E32: Manual (Cotton) | F32: Loading | G32: =$E$6 -> 0.5 | H32: 1 person/line/shift | I32: (0.5*1)*3 | J32: =G32*1*3 -> 1.5 | L32: 0 | M32: =N32 -> 2 | N32: =ROUND(J32,0) -> 2 | O32: 3 | P32: 0 | Q32: =ROUNDDOWN(N32/3,0) -> 0 | R32: =ROUNDDOWN(N32/3,0) -> 0 | S32: =N32-Q32-R32 -> 2 | T32: 0 | U32: Cotton
A33: Vapi | B33: Rugs | C33: Packing Line MP | D33: 23 | E33: Manual (Cotton) | F33: Tailor | G33: =$E$6 -> 0.5 | H33: 2 tailor/line/shift | I33: (0.5*2)*3 | J33: =G33*2*3 -> 3 | L33: 0 | M33: =N33 -> 3 | N33: =ROUND(J33,0) -> 3 | O33: 3 | P33: 0 | Q33: =ROUNDDOWN(N33/3,0) -> 1 | R33: =ROUNDDOWN(N33/3,0) -> 1 | S33: =N33-Q33-R33 -> 1 | T33: 0 | U33: Cotton
A34: Vapi | B34: Rugs | C34: Packing Line MP | D34: 24 | E34: Manual (Cotton) | F34: Finisher | G34: =$E$6 -> 0.5 | H34: 3 finisher/line/shift | I34: (0.5*3)*3 | J34: =G34*3*3 -> 4.5 | L34: 0 | M34: =N34 -> 5 | N34: =ROUND(J34,0) -> 5 | O34: 3 | P34: 0 | Q34: =ROUNDDOWN(N34/3,0) -> 1 | R34: =ROUNDDOWN(N34/3,0) -> 1 | S34: =N34-Q34-R34 -> 3 | T34: 0 | U34: Cotton
A35: Vapi | B35: Rugs | C35: Packing Line MP | D35: 25 | E35: Manual (Cotton) | F35: Hot Air | G35: =$E$6 -> 0.5 | H35: 1 person/line/shift | I35: (0.5*1)*3 | J35: =G35*1*3 -> 1.5 | L35: 0 | M35: =N35 -> 2 | N35: =ROUND(J35,0) -> 2 | O35: 3 | P35: 0 | Q35: =ROUNDDOWN(N35/3,0) -> 0 | R35: =ROUNDDOWN(N35/3,0) -> 0 | S35: =N35-Q35-R35 -> 2 | T35: 0 | U35: Cotton
A36: Vapi | B36: Rugs | C36: Packing Line MP | D36: 26 | E36: Manual (Cotton) | F36: UL & AC | G36: =$E$6 -> 0.5 | H36: 1 person/line/shift | I36: (0.5*1)*3 | J36: =G36*1*3 -> 1.5 | L36: 0 | M36: =N36 -> 2 | N36: =ROUND(J36,0) -> 2 | O36: 3 | P36: 0 | Q36: =ROUNDDOWN(N36/3,0) -> 0 | R36: =ROUNDDOWN(N36/3,0) -> 0 | S36: =N36-Q36-R36 -> 2 | T36: 0 | U36: Cotton
A37: Vapi | B37: Rugs | C37: Packing Line MP | D37: 27 | E37: Manual (Cotton) | F37: Gunner | G37: =$E$6 -> 0.5 | H37: 1 person/line/shift | I37: (0.5*1)*3 | J37: =G37*1*3 -> 1.5 | L37: 0 | M37: =N37 -> 2 | N37: =ROUND(J37,0) -> 2 | O37: 3 | P37: 0 | Q37: =ROUNDDOWN(N37/3,0) -> 0 | R37: =ROUNDDOWN(N37/3,0) -> 0 | S37: =N37-Q37-R37 -> 2 | T37: 0 | U37: Cotton
A38: Vapi | B38: Rugs | C38: Packing Line MP | D38: 28 | E38: Manual (Cotton) | F38: Poly Packer | G38: =$E$6 -> 0.5 | H38: 4 person/line/shift | I38: (0.5*4)*3 | J38: =G38*4*3 -> 6 | L38: 0 | M38: =N38 -> 6 | N38: =ROUND(J38,0) -> 6 | O38: 3 | P38: 0 | Q38: =ROUNDDOWN(N38/3,0) -> 2 | R38: =ROUNDDOWN(N38/3,0) -> 2 | S38: =N38-Q38-R38 -> 2 | T38: 0 | U38: Cotton
A39: Vapi | B39: Rugs | C39: Packing Support MP | D39: 29 | E39: Packing Support | F39: IMS | G39: 1 | H39: sum of required lines | I39: SUM(2.0+2.1+2.6+0.5) | J39: =SUM($E$3:$E$6)*3 -> 21.6 | L39: 0 | M39: =N39 -> 22 | N39: =ROUND(J39,0) -> 22 | O39: 3 | P39: 0 | Q39: =ROUNDDOWN(N39/3,0) -> 7 | R39: =ROUNDDOWN(N39/3,0) -> 7 | S39: =N39-Q39-R39 -> 8 | T39: 0
A40: Vapi | B40: Rugs | C40: Packing Support MP | D40: 30 | E40: Packing Support | F40: Material Handler | G40: 1 | H40: 4 person/shift | I40: 4*3 | J40: =4*3 -> 12 | L40: 0 | M40: =N40 -> 12 | N40: =ROUND(J40,0) -> 12 | O40: 3 | P40: 0 | Q40: =ROUNDDOWN(N40/3,0) -> 4 | R40: =ROUNDDOWN(N40/3,0) -> 4 | S40: =N40-Q40-R40 -> 4 | T40: 0
A41: Vapi | B41: Rugs | C41: Packing Support MP | D41: 31 | E41: Packing Support | F41: Line Jobber | G41: 1 | H41: sum of required lines | I41: SUM(2.0+2.1+2.6+0.5)*3 | J41: =SUM($E$3:$E$6)*3 -> 21.6 | L41: 0 | M41: =N41 -> 22 | N41: =ROUND(J41,0) -> 22 | O41: 3 | P41: 0 | Q41: =ROUNDDOWN(N41/3,0) -> 7 | R41: =ROUNDDOWN(N41/3,0) -> 7 | S41: =N41-Q41-R41 -> 8 | T41: 0
A42: Vapi | B42: Rugs | C42: Packing Support MP | D42: 32 | E42: Packing Support | F42: Rework (Stain/Coating) | G42: 1 | H42: half of total lines | I42: ROUNDUP(SUM(lines)/2,0)*3 | J42: =ROUNDUP(SUM($E$3:$E$6)/2,0)*3 -> 12 | L42: 0 | M42: =N42 -> 12 | N42: =ROUND(J42,0) -> 12 | O42: 3 | P42: 0 | Q42: =ROUNDDOWN(N42/3,0) -> 4 | R42: =ROUNDDOWN(N42/3,0) -> 4 | S42: =N42-Q42-R42 -> 4 | T42: 0
A43: Vapi | B43: Rugs | C43: Packing Support MP | D43: 33 | E43: Packing Support | F43: Mender | G43: 1 | H43: half of total lines | I43: ROUNDUP(SUM(lines)/2,0)*3 | J43: =ROUNDUP(SUM($E$3:$E$6)/2,0)*3 -> 12 | L43: 0 | M43: =N43 -> 12 | N43: =ROUND(J43,0) -> 12 | O43: 3 | P43: 0 | Q43: =ROUNDDOWN(N43/3,0) -> 4 | R43: =ROUNDDOWN(N43/3,0) -> 4 | S43: =N43-Q43-R43 -> 4 | T43: 0
A44: Vapi | B44: Rugs | C44: Packing Support MP | D44: 34 | E44: Packing Support | F44: Carton Pkg | G44: 1 | H44: 3 x total required lines | I44: SUM(lines)*3*3 | J44: =SUM($E$3:$E$6)*3*3 -> 64.8 | L44: 0 | M44: =N44 -> 65 | N44: =ROUND(J44,0) -> 65 | O44: 3 | P44: 0 | Q44: =ROUNDDOWN(N44/3,0) -> 21 | R44: =ROUNDDOWN(N44/3,0) -> 21 | S44: =N44-Q44-R44 -> 23 | T44: 0
...

Sheet Dye_Mc
A1: MACHINE | B1: CAPACITY | C1: CHENILLE | D1: COTTON | E1: DRYLON | F1: Machine_count | G1: Machine_count * DRYLON or Machine_count * COTTON | H1: DRYLON_Production | I1: MC | J1: EZM | K1: Paddle
A2: EZM-01 | B2: 120 | E2: 943.0344 | F2: 1 | G2: 943.0344 | H2: 40066.828 | I2: Drylon | J2: 10 | K2: 5
A3: EZM-02 | B3: 120 | E3: 943.0344 | F3: 1 | G3: 943.0344 | H3: COTTON_Production | I3: Cotton | J3: 0 | K3: 2
A4: EZM-03 | B4: 120 | E4: 943.0344 | F4: 1 | G4: 943.0344 | H4: 2365.3196 | I4: Total | J4: 10 | K4: 7
A5: EZM-04 | B5: 120 | E5: 943.0344 | F5: 1 | G5: 943.0344 | I5: Avail | J5: 14 | K5: 17
A6: EZM-05 | B6: 120 | E6: 943.0344 | F6: 1 | G6: 943.0344 | I6: Short/Excess | J6: 4 | K6: 10
A7: EZM-06 | B7: 120 | E7: 943.0344 | F7: 0 | G7: 0
A8: EZM-07 | B8: 220 | E8: 1728.8964 | F8: 1 | G8: 1728.8964
A9: EZM-08 | B9: 220 | E9: 1728.8964 | F9: 1 | G9: 1728.8964
A10: EZM-09 | B10: 220 | E10: 1728.8964 | F10: 1 | G10: 1728.8964
A11: EZM-10 | B11: 220 | E11: 1728.8964 | F11: 1 | G11: 1728.8964
A12: EZM-11 | B12: 220 | E12: 1728.8964 | F12: 1 | G12: 1728.8964
A13: EZM012 | B13: 220 | E13: 1728.8964 | F13: 0 | G13: 0
A14: PD-03 | B14: 1050 | E14: 6417.873 | F14: 2 | G14: =F14*E14 -> 12835.746
A15: PD-04 | B15: 1050 | E15: 6417.873 | F15: 1 | G15: =F15*E15 -> 6417.873
A16: PD-07 | B16: 750 | E16: 4584.195 | F16: 0 | G16: =F16*E16 -> 0
A17: PD-08 | B17: 750 | E17: 4584.195 | F17: 1 | G17: =F17*E17 -> 4584.195
A18: PD-09 | B18: 500 | E18: 3056.13 | F18: 1 | G18: =F18*E18 -> 3056.13
A19: EZM-12 | B19: 220 | D19: 441.936 | F19: 0 | G19: 0
A20: EZM-13 | B20: 220 | D20: 441.936 | F20: 0 | G20: 0
A21: EZM-14 | B21: 220 | D21: 441.936 | F21: 0 | G21: 0
A22: EZM-15 | B22: 220 | D22: 441.936 | F22: 0 | G22: 0
A23: PD-01 | B23: 1050 | D23: 1792.854 | F23: 1 | G23: 1792.854
A24: PD-02 | B24: 1050 | D24: 1792.854 | F24: 1 | G24: 1792.854
A25: PD-05 | B25: 1050 | D25: 1792.854 | F25: 0 | G25: 0
A26: PD-06 | B26: 1050 | D26: 1792.854 | F26: 0 | G26: 0
A27: PD-10 | B27: 300 | D27: 512.244 | F27: 0 | G27: 0
A28: PD-11 | B28: 300 | D28: 512.244 | F28: 0 | G28: 0
A29: PD-12 | B29: 1050 | D29: 1792.854 | F29: 0 | G29: 0
A30: PD-13 | B30: 1050 | D30: 1792.854 | F30: 0 | G30: 0
... A34: PD-17 | B34: 1050 | D34: 1792.854 | F34: 0 | G34: 0

Sheet Hydro 
A1: Efficiency | B1: Required Pcs | C1: additional Req | D1: M/s Capacity Proposed | E1: No. Of Batch | F1: Prod/mc/day (Kgs) | G1: Pcs/day/mc | H1: Total M/c Req
A2: 95 | B2: =Capacity!F2+Capacity!F3+Capacity!F5 -> 43452.538 | D2: 220 | E2: 36 | F2: =E2*D2*A2% -> 7524 | G2: =F2*0.98 -> 7373.52 | H2: =ROUND(B2/F2,0) -> 6

Sheet Packing
A1: Main_Group | B1: Sub_Group | C1: Category | D1: Subcategory | E1: Asking_Rate_Per_Day
A2: Packing | C2: Packing | D2: Carving | E2: 244
A3: Packing | C3: Packing | D3: Chenile | E3: 11889
A4: Packing | C4: Packing | D4: non carving | E4: 1994
A5: Packing | C5: Packing | D5: Roll | E5: 354
A6: Packing | C6: Packing | D6: Rugs | E6: 53481
A7: Packing | C7: Packing | D7: Grand Total | E7: 67963
A8: Packing | C8: Packing | D8: Repacking/buffer/DG | E8: 2080
A9: C&S | B9: Overedging | C9: Stitching Type | D9: Drylon Washing | E9: 10247
A10: C&S | B10: Overedging | C10: Stitching Type | D10: Non dyeing | E10: 1190
A11: C&S | B11: Overedging | C11: Stitching Type | D11: tumble | E11: 13563
A12: C&S | B12: Overedging | C12: Stitching Type | D12: Overedging Total | E12: 24999
A13: C&S | B13: Union | C13: Stitching Type | D13: Cotton dyeing | E13: 617
A14: C&S | B14: Union | C14: Stitching Type | D14: Drylon Washing | E14: 28424
A15: C&S | B15: Union | C15: Stitching Type | D15: Polyester dyeing | E15: 12257
A16: C&S | B16: Union | C16: Stitching Type | D16: Union Total | E16: 41297
A17: C&S | C17: Stitching Type | D17: Grand Total | E17: 66296
A18: Grey Issue | C18: Process | D18: Cotton dyeing | E18: 2294
A19: Grey Issue | C19: Process | D19: Drylon Washing | E19: 38670
A20: Grey Issue | C20: Process | D20: Non dyeing | E20: 1190
A21: Grey Issue | C21: Process | D21: Polyester dyeing | E21: 12257
A22: Grey Issue | C22: Process | D22: tumble | E22: 13563
A23: Grey Issue | C23: Process | D23: Grand Total | E23: 67973
A24: Processing | C24: Process | D24: Cotton dyeing | E24: 2365
A25: Processing | C25: Process | D25: Drylon Washing | E25: 40067
A26: Processing | C26: Process | D26: Polyester dyeing | E26: 12257
A27: Processing | C27: Process | D27: MT (PC/Day) | E27: =(54.42*1.1)*3.9 -> 233.4618
A28: Processing | C28: Process | D28: TT (PC/Day) | E28: =E24-E27 -> 2131.5382
A29: Processing | C29: Process | D29: Grand Total | E29: 54689
A30: Coating | C30: Coating | D30: cotton | E30: 81
A31: Coating | C31: Coating | D31: Foam | E31: 6881
A32: Coating | C32: Coating | D32: Grand Total | E32: 6962
A33: Machine Tufting | C33: M/c | D33: 1/8 Cut | E33: 1201
A34: Machine Tufting | C34: M/c | D34: 1/8 MLCL | E34: 1696
A35: Machine Tufting | C35: M/c | D35: 1/10 Loop | E35: 149
A36: Machine Tufting | C36: M/c | D36: 3/8 Cut | E36: 375
A37: Machine Tufting | C37: M/c | D37: 3/8 Loop | E37: 1505
A38: Machine Tufting | C38: M/c | D38: Grand Total | E38: 4926
A39: Table Tufting | C39: M/c | D39: 1/4 Rev | E39: 611
A40: Table Tufting | C40: M/c | D40: 3/16 Cut | E40: 1067
...

Sheet Capacity
A1: VAPI Location | B1: Avg. area/Pcs | C1: PCS /DAY | D1: MTR/ DAY | E1: Lac SQM/ Month | F1: PCS /DAY | G1: MTR/ DAY | H1: Lac SQM/ Month
A2: Cotton-M/C Tufting | B2: 0.41 | C2: 7000 | D2: =C2*B2/3.9 -> 735.89744 | E2: =C2*B2*30/100000 -> 0.861 | F2: =Packing!E27 -> 233.4618 | G2: =F2*B2/3.9 -> 24.54342 | H2: =F2*B2*30/100000 -> 0.028715801
A3: Cotton-Table Tufting | B3: 0.4 | C3: 5000 | D3: =C3*B3/3.9 -> 512.82051 | E3: =C3*B3*30/100000 -> 0.6 | F3: =Packing!E28 -> 2131.5382 | G3: =F3*B3/3.9 -> 218.6193 | H3: =F3*B3*30/100000 -> 0.25578458
A4: Chenille | B4: 0.4 | C4: 28000 | D4: =C4*B4/3.9 -> 2871.7949 | E4: =C4*B4*30/100000 -> 3.36 | F4: =Packing!E3 -> 11889 | G4: =F4*B4/3.9 -> 1219.3846 | H4: =F4*B4*30/100000 -> 1.42668
A5: Bath Rugs (Wash) | B5: 0.42 | C5: 47000 | D5: =C5*B5/3.9 -> 5061.5385 | E5: =C5*B5*30/100000 -> 5.922 | F5: =Packing!E7-F2-F4-F6 -> 41087.538 | G5: =F5*B5/3.9 -> 4424.8118 | H5: =F5*B5*30/100000 -> 5.1770298
A6: Bath Rugs (Non- Wash with Tumble) | B6: 0.42 | C6: 9700 | D6: =C6*B6/3.9 -> 1044.6154 | E6: =C6*B6*30/100000 -> 1.2222 | F6: =Packing!E10+Packing!E11 -> 14753 | G6: =F6*B6/3.9 -> 1588.7846 | H6: =F6*B6*30/100000 -> 1.858878
C7: =SUM(C2:C6) -> 96700 | D7: =SUM(D2:D6) -> 10226.667 | E7: =SUM(E2:E6) -> 11.9652 | F7: =SUM(F2:F6) -> 70094.538 | G7: =SUM(G2:G6) -> 7476.1438 | H7: =SUM(H2:H6) -> 8.7470882

Sheet Coating
A1: Parameter | B1: Material | C1: Value
A2: Speed | B2: Cotton | C2: 5.5
A3: Speed | B3: Drylon | C3: 7
A4: Efficiency | B4: Cotton | C4: 0.9
A5: Efficiency | B5: Drylon | C5: 0.9
A6: Utilisation | B6: Cotton | C6: 0.97
A7: Utilisation | B7: Drylon | C7: 0.97
A8: Effective Production | B8: Cotton | C8: =C2*1400*C5*C6 -> 6722.1
A9: Effective Production | B9: Drylon | C9: =C3*1400*C5*C7 -> 8555.4
A10: Required Production | B10: Cotton | C10: 0
A11: Required Production | B11: Drylon | C11: =SUM(Capacity!G5:G6)*1.05 -> 6314.2762
A12: Machines Required | B12: Cotton | C12: =IFERROR(C8/C10,0) -> 0
A13: Machines Required | B13: Drylon | C13: =C11/C9 -> 0.73804571
A14: Machines Required | B14: Total | C14: =ROUND(0.718,0) -> 1

Sheet CS
A1: Section | B1: Process | C1: Metric | D1: Value
A2: Production | B2: Cotton Dyeing (TT) | C2: Pcs/Day | D2: =Capacity!F3 -> 2131.5382
A3: Production | B3: Cotton Dyeing (TT) | C3: Pcs/Month | D3: =D2*25 -> 53288.455
A4: Production | B4: Cotton Dyeing (TT) | C4: Linear Mtr | D4: 0
A5: Production | B5: Cotton Dyeing (TT) | C5: Union | D5: 0
A6: Production | B6: Cotton Dyeing (TT) | C6: Mat | D6: 0
A7: Production | B7: Cotton Dyeing (TT) | C7: Shape/Design | D7: 0
A8: Production | B8: Cotton Dyeing (TT) | C8: Over Edging | D8: 0
A9: Production | B9: Cotton Dyeing (MT) | C9: Pcs/Day | D9: =Capacity!F2 -> 233.4618
A10: Production | B10: Cotton Dyeing (MT) | C10: Pcs/Month | D10: =D9*25 -> 5836.545
A11: Production | B11: Cotton Dyeing (MT) | C11: Linear Mtr | D11: =Capacity!G2 -> 24.54342
A12: Production | B12: Cotton Dyeing (MT) | C12: Union | D12: =D9 -> 233.4618
A13: Production | B13: Cotton Dyeing (MT) | C13: Mat | D13: =D9 -> 233.4618
A14: Production | B14: Cotton Dyeing (MT) | C14: Shape/Design | D14: 0
A15: Production | B15: Cotton Dyeing (MT) | C15: Over Edging | D15: 0
A16: Production | B16: Drylon (Washing) | C16: Pcs/Day | D16: =Capacity!F5 -> 41087.538
A17: Production | B17: Drylon (Washing) | C17: Pcs/Month | D17: =D16*25 -> 1027188.5
A18: Production | B18: Drylon (Washing) | C18: Linear Mtr | D18: =Capacity!G5 -> 4424.8118
A19: Production | B19: Drylon (Washing) | C19: Union | D19: =D16*0.85 -> 34924.407
A20: Production | B20: Drylon (Washing) | C20: Over Edging | D20: =(D16-D19) -> 6163.1307
A21: Production | B21: Drylon (Washing) | C21: Mat | D21: =D16*0.5 -> 20543.769
A22: Production | B22: Drylon (Washing) | C22: Shape/Design | D22: 1000
A23: Production | B23: Drylon_Rugs (Non_Washing) | C23: Pcs/Day | D23: =Capacity!F6 -> 14753
A24: Production | B24: Drylon_Rugs (Non_Washing) | C24: Pcs/Month | D24: =D23*25 -> 368825
A25: Production | B25: Drylon_Rugs (Non_Washing) | C25: Linear Mtr | D25: =Capacity!G6 -> 1588.7846
A26: Production | B26: Drylon_Rugs (Non_Washing) | C26: Union | D26: 0
A27: Production | B27: Drylon_Rugs (Non_Washing) | C27: Over Edging | D27: =D23 -> 14753
A28: Production | B28: Drylon_Rugs (Non_Washing) | C28: Mat | D28: =D27-D29 -> 7253
A29: Production | B29: Drylon_Rugs (Non_Washing) | C29: Shape/Design | D29: 7500
A30: Production | B30: Carpet_Rolling | C30: Pcs/Day | D30: 0
A31: Production | B31: Carpet_Rolling | C31: Pcs/Month | D31: =D30*25 -> 0
A32: Production | B32: Carpet_Rolling | C32: Linear Mtr | D32: 0
A33: Production | B33: Carpet_Rolling | C33: Union | D33: 0
A34: Production | B34: Carpet_Rolling | C34: Over Edging | D34: 0
A35: Production | B35: Carpet_Rolling | C35: Mat | D35: 0
A36: Production | B36: Carpet_Rolling | C36: Shape/Design | D36: 0
A37: Production | B37: Chenille | C37: Pcs/Day | D37: =Capacity!F4 -> 11889
A38: Production | B38: Chenille | C38: Pcs/Month | D38: =D37*25 -> 297225
A39: Production | B39: Chenille | C39: Linear Mtr | D39: 0
A40: Production | B40: Chenille | C40: Union | D40: =D37 -> 11889
...
